Workbook

Sheet Sign-ups
A1: HEADERS | B1: HEELERS | D1: How to use
A2: Cody Reeves | B2: Tyler Branch | D2: 1. Type or paste header names in column A (starting A2).
A3: Trevor James | B3: Luke Ramsey | D3: 2. Type or paste heeler names in column B (starting B2).
A4: Wyatt Holloway | B4: Cody Reeves | D4: 3. 'Teams' tab auto-generates pairings.
A5: Jess McCoy | B5: Hank Daniels | D5: 4. 'Slips' tab is print-ready time slips, 3 per page.
A6: Sam Tatum | B6: Cole Briggs | D6: 5. Riders signed up for both header AND heeler:
A7: Bo Whitaker | D7: spell name IDENTICALLY in A and B - auto-skipped.
D8: 6. If 'Conflict?' lights up red on Teams, swap that row
D9: with one nearby to clear the warning.
D10: 7. Capacity: up to 50 headers x 50 heelers.

Sheet Teams
A1: TEAM # | B1: HEADER | C1: HEELER | D1: Conflict? | F1: Notes
A2: =IF((ROW()-1)<=MAX(_calc!$E$2:$E$2501),(ROW()-1),"") -> 1 | B2: =IF((ROW()-1)<=MAX(_calc!$E$2:$E$2501),INDEX(_calc!$B$2:$B$2501,MATCH((ROW()-1),_calc!$E$2:$E$2501,0)),"") -> Cody Reeves | C2: =IF((ROW()-1)<=MAX(_calc!$E$2:$E$2501),INDEX(_calc!$C$2:$C$2501,MATCH((ROW()-1),_calc!$E$2:$E$2501,0)),"") -> Tyler Branch | D2: ="" | F2: Order rotates each round so headers and heelers alternate.
A3: =IF((ROW()-1)<=MAX(_calc!$E$2:$E$2501),(ROW()-1),"") -> 2 | B3: =IF((ROW()-1)<=MAX(_calc!$E$2:$E$2501),INDEX(_calc!$B$2:$B$2501,MATCH((ROW()-1),_calc!$E$2:$E$2501,0)),"") -> Trevor James | C3: =IF((ROW()-1)<=MAX(_calc!$E$2:$E$2501),INDEX(_calc!$C$2:$C$2501,MATCH((ROW()-1),_calc!$E$2:$E$2501,0)),"") -> Luke Ramsey | D3: =IF(B3="","",IF(AND(B3=B2,C3=C2),"Both",IF(B3=B2,"Header repeat",IF(C3=C2,"Heeler repeat","")))) | F3: Riders signed up for both: spell name exactly the same in A and B.
A4: =IF((ROW()-1)<=MAX(_calc!$E$2:$E$2501),(ROW()-1),"") -> 3 | B4: =IF((ROW()-1)<=MAX(_calc!$E$2:$E$2501),INDEX(_calc!$B$2:$B$2501,MATCH((ROW()-1),_calc!$E$2:$E$2501,0)),"") -> Wyatt Holloway | C4: =IF((ROW()-1)<=MAX(_calc!$E$2:$E$2501),INDEX(_calc!$C$2:$C$2501,MATCH((ROW()-1),_calc!$E$2:$E$2501,0)),"") -> Cody Reeves | D4: =IF(B4="","",IF(AND(B4=B3,C4=C3),"Both",IF(B4=B3,"Header repeat",IF(C4=C3,"Heeler repeat","")))) | F4: Works on any Excel version.
A5: =IF((ROW()-1)<=MAX(_calc!$E$2:$E$2501),(ROW()-1),"") -> 4 | B5: =IF((ROW()-1)<=MAX(_calc!$E$2:$E$2501),INDEX(_calc!$B$2:$B$2501,MATCH((ROW()-1),_calc!$E$2:$E$2501,0)),"") -> Jess McCoy | C5: =IF((ROW()-1)<=MAX(_calc!$E$2:$E$2501),INDEX(_calc!$C$2:$C$2501,MATCH((ROW()-1),_calc!$E$2:$E$2501,0)),"") -> Hank Daniels | D5: =IF(B5="","",IF(AND(B5=B4,C5=C4),"Both",IF(B5=B4,"Header repeat",IF(C5=C4,"Heeler repeat","")))) | F5: Capacity: up to 50 headers x 50 heelers (2,500 teams max).
A6: =IF((ROW()-1)<=MAX(_calc!$E$2:$E$2501),(ROW()-1),"") -> 5 | B6: =IF((ROW()-1)<=MAX(_calc!$E$2:$E$2501),INDEX(_calc!$B$2:$B$2501,MATCH((ROW()-1),_calc!$E$2:$E$2501,0)),"") -> Sam Tatum | C6: =IF((ROW()-1)<=MAX(_calc!$E$2:$E$2501),INDEX(_calc!$C$2:$C$2501,MATCH((ROW()-1),_calc!$E$2:$E$2501,0)),"") -> Cole Briggs | D6: =IF(B6="","",IF(AND(B6=B5,C6=C5),"Both",IF(B6=B5,"Header repeat",IF(C6=C5,"Heeler repeat",""))))
A7: =IF((ROW()-1)<=MAX(_calc!$E$2:$E$2501),(ROW()-1),"") -> 6 | B7: =IF((ROW()-1)<=MAX(_calc!$E$2:$E$2501),INDEX(_calc!$B$2:$B$2501,MATCH((ROW()-1),_calc!$E$2:$E$2501,0)),"") -> Bo Whitaker | C7: =IF((ROW()-1)<=MAX(_calc!$E$2:$E$2501),INDEX(_calc!$C$2:$C$2501,MATCH((ROW()-1),_calc!$E$2:$E$2501,0)),"") -> Tyler Branch | D7: =IF(B7="","",IF(AND(B7=B6,C7=C6),"Both",IF(B7=B6,"Header repeat",IF(C7=C6,"Heeler repeat",""))))
A8: =IF((ROW()-1)<=MAX(_calc!$E$2:$E$2501),(ROW()-1),"") -> 7 | B8: =IF((ROW()-1)<=MAX(_calc!$E$2:$E$2501),INDEX(_calc!$B$2:$B$2501,MATCH((ROW()-1),_calc!$E$2:$E$2501,0)),"") -> Cody Reeves | C8: =IF((ROW()-1)<=MAX(_calc!$E$2:$E$2501),INDEX(_calc!$C$2:$C$2501,MATCH((ROW()-1),_calc!$E$2:$E$2501,0)),"") -> Luke Ramsey | D8: =IF(B8="","",IF(AND(B8=B7,C8=C7),"Both",IF(B8=B7,"Header repeat",IF(C8=C7,"Heeler repeat",""))))
A9: =IF((ROW()-1)<=MAX(_calc!$E$2:$E$2501),(ROW()-1),"") -> 8 | B9: =IF((ROW()-1)<=MAX(_calc!$E$2:$E$2501),INDEX(_calc!$B$2:$B$2501,MATCH((ROW()-1),_calc!$E$2:$E$2501,0)),"") -> Trevor James | C9: =IF((ROW()-1)<=MAX(_calc!$E$2:$E$2501),INDEX(_calc!$C$2:$C$2501,MATCH((ROW()-1),_calc!$E$2:$E$2501,0)),"") -> Cody Reeves | D9: =IF(B9="","",IF(AND(B9=B8,C9=C8),"Both",IF(B9=B8,"Header repeat",IF(C9=C8,"Heeler repeat",""))))
A10: =IF((ROW()-1)<=MAX(_calc!$E$2:$E$2501),(ROW()-1),"") -> 9 | B10: =IF((ROW()-1)<=MAX(_calc!$E$2:$E$2501),INDEX(_calc!$B$2:$B$2501,MATCH((ROW()-1),_calc!$E$2:$E$2501,0)),"") -> Wyatt Holloway | C10: =IF((ROW()-1)<=MAX(_calc!$E$2:$E$2501),INDEX(_calc!$C$2:$C$2501,MATCH((ROW()-1),_calc!$E$2:$E$2501,0)),"") -> Hank Daniels | D10: =IF(B10="","",IF(AND(B10=B9,C10=C9),"Both",IF(B10=B9,"Header repeat",IF(C10=C9,"Heeler repeat",""))))
A11: =IF((ROW()-1)<=MAX(_calc!$E$2:$E$2501),(ROW()-1),"") -> 10 | B11: =IF((ROW()-1)<=MAX(_calc!$E$2:$E$2501),INDEX(_calc!$B$2:$B$2501,MATCH((ROW()-1),_calc!$E$2:$E$2501,0)),"") -> Jess McCoy | C11: =IF((ROW()-1)<=MAX(_calc!$E$2:$E$2501),INDEX(_calc!$C$2:$C$2501,MATCH((ROW()-1),_calc!$E$2:$E$2501,0)),"") -> Cole Briggs | D11: =IF(B11="","",IF(AND(B11=B10,C11=C10),"Both",IF(B11=B10,"Header repeat",IF(C11=C10,"Heeler repeat",""))))
A12: =IF((ROW()-1)<=MAX(_calc!$E$2:$E$2501),(ROW()-1),"") -> 11 | B12: =IF((ROW()-1)<=MAX(_calc!$E$2:$E$2501),INDEX(_calc!$B$2:$B$2501,MATCH((ROW()-1),_calc!$E$2:$E$2501,0)),"") -> Sam Tatum | C12: =IF((ROW()-1)<=MAX(_calc!$E$2:$E$2501),INDEX(_calc!$C$2:$C$2501,MATCH((ROW()-1),_calc!$E$2:$E$2501,0)),"") -> Tyler Branch | D12: =IF(B12="","",IF(AND(B12=B11,C12=C11),"Both",IF(B12=B11,"Header repeat",IF(C12=C11,"Heeler repeat",""))))
A13: =IF((ROW()-1)<=MAX(_calc!$E$2:$E$2501),(ROW()-1),"") -> 12 | B13: =IF((ROW()-1)<=MAX(_calc!$E$2:$E$2501),INDEX(_calc!$B$2:$B$2501,MATCH((ROW()-1),_calc!$E$2:$E$2501,0)),"") -> Bo Whitaker | C13: =IF((ROW()-1)<=MAX(_calc!$E$2:$E$2501),INDEX(_calc!$C$2:$C$2501,MATCH((ROW()-1),_calc!$E$2:$E$2501,0)),"") -> Luke Ramsey | D13: =IF(B13="","",IF(AND(B13=B12,C13=C12),"Both",IF(B13=B12,"Header repeat",IF(C13=C12,"Heeler repeat",""))))
A14: =IF((ROW()-1)<=MAX(_calc!$E$2:$E$2501),(ROW()-1),"") -> 13 | B14: =IF((ROW()-1)<=MAX(_calc!$E$2:$E$2501),INDEX(_calc!$B$2:$B$2501,MATCH((ROW()-1),_calc!$E$2:$E$2501,0)),"") -> Trevor James | C14: =IF((ROW()-1)<=MAX(_calc!$E$2:$E$2501),INDEX(_calc!$C$2:$C$2501,MATCH((ROW()-1),_calc!$E$2:$E$2501,0)),"") -> Hank Daniels | D14: =IF(B14="","",IF(AND(B14=B13,C14=C13),"Both",IF(B14=B13,"Header repeat",IF(C14=C13,"Heeler repeat",""))))
A15: =IF((ROW()-1)<=MAX(_calc!$E$2:$E$2501),(ROW()-1),"") -> 14 | B15: =IF((ROW()-1)<=MAX(_calc!$E$2:$E$2501),INDEX(_calc!$B$2:$B$2501,MATCH((ROW()-1),_calc!$E$2:$E$2501,0)),"") -> Wyatt Holloway | C15: =IF((ROW()-1)<=MAX(_calc!$E$2:$E$2501),INDEX(_calc!$C$2:$C$2501,MATCH((ROW()-1),_calc!$E$2:$E$2501,0)),"") -> Cole Briggs | D15: =IF(B15="","",IF(AND(B15=B14,C15=C14),"Both",IF(B15=B14,"Header repeat",IF(C15=C14,"Heeler repeat",""))))
A16: =IF((ROW()-1)<=MAX(_calc!$E$2:$E$2501),(ROW()-1),"") -> 15 | B16: =IF((ROW()-1)<=MAX(_calc!$E$2:$E$2501),INDEX(_calc!$B$2:$B$2501,MATCH((ROW()-1),_calc!$E$2:$E$2501,0)),"") -> Jess McCoy | C16: =IF((ROW()-1)<=MAX(_calc!$E$2:$E$2501),INDEX(_calc!$C$2:$C$2501,MATCH((ROW()-1),_calc!$E$2:$E$2501,0)),"") -> Tyler Branch | D16: =IF(B16="","",IF(AND(B16=B15,C16=C15),"Both",IF(B16=B15,"Header repeat",IF(C16=C15,"Heeler repeat",""))))
A17: =IF((ROW()-1)<=MAX(_calc!$E$2:$E$2501),(ROW()-1),"") -> 16 | B17: =IF((ROW()-1)<=MAX(_calc!$E$2:$E$2501),INDEX(_calc!$B$2:$B$2501,MATCH((ROW()-1),_calc!$E$2:$E$2501,0)),"") -> Sam Tatum | C17: =IF((ROW()-1)<=MAX(_calc!$E$2:$E$2501),INDEX(_calc!$C$2:$C$2501,MATCH((ROW()-1),_calc!$E$2:$E$2501,0)),"") -> Luke Ramsey | D17: =IF(B17="","",IF(AND(B17=B16,C17=C16),"Both",IF(B17=B16,"Header repeat",IF(C17=C16,"Heeler repeat",""))))
... A2501: =IF((ROW()-1)<=MAX(_calc!$E$2:$E$2501),(ROW()-1),"") | B2501: =IF((ROW()-1)<=MAX(_calc!$E$2:$E$2501),INDEX(_calc!$B$2:$B$2501,MATCH((ROW()-1),_calc!$E$2:$E$2501,0)),"") | C2501: =IF((ROW()-1)<=MAX(_calc!$E$2:$E$2501),INDEX(_calc!$C$2:$C$2501,MATCH((ROW()-1),_calc!$E$2:$E$2501,0)),"") | D2501: =IF(B2501="","",IF(AND(B2501=B2500,C2501=C2500),"Both",IF(B2501=B2500,"Header repeat",IF(C2501=C2500,"Heeler repeat",""))))

Sheet Slips
A1: =IF(MAX(_calc!$E$2:$E$2501)=0,"Add teams on the Sign-ups tab to generate slips.","Pages to print: 1 through "&CEILING(MAX(_calc!$E$2:$E$2501),3)/3&" ("&MAX(_calc!$E$2:$E$2501)&" teams)") -> Pages to print: 1 through 10 (29 teams)
A2: Header: | B2: =IF(Teams!$A$2="","",Teams!$B$2) -> Cody Reeves | D2: Heeler: | E2: =IF(Teams!$A$2="","",Teams!$C$2) -> Tyler Branch
A4: Round 1: | D4: Round 2:
A6: Short Go: | D6: Total:
A9: Header: | B9: =IF(Teams!$A$3="","",Teams!$B$3) -> Trevor James | D9: Heeler: | E9: =IF(Teams!$A$3="","",Teams!$C$3) -> Luke Ramsey
A11: Round 1: | D11: Round 2:
A13: Short Go: | D13: Total:
A16: Header: | B16: =IF(Teams!$A$4="","",Teams!$B$4) -> Wyatt Holloway | D16: Heeler: | E16: =IF(Teams!$A$4="","",Teams!$C$4) -> Cody Reeves
A18: Round 1: | D18: Round 2:
A20: Short Go: | D20: Total:
A23: Header: | B23: =IF(Teams!$A$5="","",Teams!$B$5) -> Jess McCoy | D23: Heeler: | E23: =IF(Teams!$A$5="","",Teams!$C$5) -> Hank Daniels
A25: Round 1: | D25: Round 2:
A27: Short Go: | D27: Total:
A30: Header: | B30: =IF(Teams!$A$6="","",Teams!$B$6) -> Sam Tatum | D30: Heeler: | E30: =IF(Teams!$A$6="","",Teams!$C$6) -> Cole Briggs
A32: Round 1: | D32: Round 2:
A34: Short Go: | D34: Total:
A37: Header: | B37: =IF(Teams!$A$7="","",Teams!$B$7) -> Bo Whitaker | D37: Heeler: | E37: =IF(Teams!$A$7="","",Teams!$C$7) -> Tyler Branch
A39: Round 1: | D39: Round 2:
A41: Short Go: | D41: Total:
A44: Header: | B44: =IF(Teams!$A$8="","",Teams!$B$8) -> Cody Reeves | D44: Heeler: | E44: =IF(Teams!$A$8="","",Teams!$C$8) -> Luke Ramsey
A46: Round 1: | D46: Round 2:
A48: Short Go: | D48: Total:
A51: Header: | B51: =IF(Teams!$A$9="","",Teams!$B$9) -> Trevor James | D51: Heeler: | E51: =IF(Teams!$A$9="","",Teams!$C$9) -> Cody Reeves
A53: Round 1: | D53: Round 2:
A55: Short Go: | D55: Total:
A58: Header: | B58: =IF(Teams!$A$10="","",Teams!$B$10) -> Wyatt Holloway | D58: Heeler: | E58: =IF(Teams!$A$10="","",Teams!$C$10) -> Hank Daniels
A60: Round 1: | D60: Round 2:
A62: Short Go: | D62: Total:
A65: Header: | B65: =IF(Teams!$A$11="","",Teams!$B$11) -> Jess McCoy | D65: Heeler: | E65: =IF(Teams!$A$11="","",Teams!$C$11) -> Cole Briggs
A67: Round 1: | D67: Round 2:
A69: Short Go: | D69: Total:
A72: Header: | B72: =IF(Teams!$A$12="","",Teams!$B$12) -> Sam Tatum | D72: Heeler: | E72: =IF(Teams!$A$12="","",Teams!$C$12) -> Tyler Branch
A74: Round 1: | D74: Round 2:
A76: Short Go: | D76: Total:
A79: Header: | B79: =IF(Teams!$A$13="","",Teams!$B$13) -> Bo Whitaker | D79: Heeler: | E79: =IF(Teams!$A$13="","",Teams!$C$13) -> Luke Ramsey
A81: Round 1: | D81: Round 2:
A83: Short Go: | D83: Total:
A86: Header: | B86: =IF(Teams!$A$14="","",Teams!$B$14) -> Trevor James | D86: Heeler: | E86: =IF(Teams!$A$14="","",Teams!$C$14) -> Hank Daniels
A88: Round 1: | D88: Round 2:
A90: Short Go: | D90: Total:
...

Sheet _calc
A1: k | B1: header | C1: heeler | D1: valid | E1: valid_count
A2: =(ROW()-2) -> 0 | B2: =IF((ROW()-2)<COUNTA('Sign-ups'!$A$2:$A$51)*COUNTA('Sign-ups'!$B$2:$B$51),INDEX('Sign-ups'!$A$2:$A$51,MOD((ROW()-2),MAX(1,COUNTA('Sign-ups'!$A$2:$A$51)))+1),"") -> Cody Reeves | C2: =IF((ROW()-2)<COUNTA('Sign-ups'!$A$2:$A$51)*COUNTA('Sign-ups'!$B$2:$B$51),INDEX('Sign-ups'!$B$2:$B$51,MOD(MOD((ROW()-2),MAX(1,COUNTA('Sign-ups'!$A$2:$A$51)))+INT((ROW()-2)/MAX(1,COUNTA('Sign-ups'!$A$2:$A$51))),MAX(1,COUNTA('Sign-ups'!$B$2:$B$51)))+1),"") -> Tyler Branch | D2: =IF(AND(B2<>"",C2<>"",B2<>C2),1,0) -> 1 | E2: =D2 -> 1
A3: =(ROW()-2) -> 1 | B3: =IF((ROW()-2)<COUNTA('Sign-ups'!$A$2:$A$51)*COUNTA('Sign-ups'!$B$2:$B$51),INDEX('Sign-ups'!$A$2:$A$51,MOD((ROW()-2),MAX(1,COUNTA('Sign-ups'!$A$2:$A$51)))+1),"") -> Trevor James | C3: =IF((ROW()-2)<COUNTA('Sign-ups'!$A$2:$A$51)*COUNTA('Sign-ups'!$B$2:$B$51),INDEX('Sign-ups'!$B$2:$B$51,MOD(MOD((ROW()-2),MAX(1,COUNTA('Sign-ups'!$A$2:$A$51)))+INT((ROW()-2)/MAX(1,COUNTA('Sign-ups'!$A$2:$A$51))),MAX(1,COUNTA('Sign-ups'!$B$2:$B$51)))+1),"") -> Luke Ramsey | D3: =IF(AND(B3<>"",C3<>"",B3<>C3),1,0) -> 1 | E3: =E2+D3 -> 2
A4: =(ROW()-2) -> 2 | B4: =IF((ROW()-2)<COUNTA('Sign-ups'!$A$2:$A$51)*COUNTA('Sign-ups'!$B$2:$B$51),INDEX('Sign-ups'!$A$2:$A$51,MOD((ROW()-2),MAX(1,COUNTA('Sign-ups'!$A$2:$A$51)))+1),"") -> Wyatt Holloway | C4: =IF((ROW()-2)<COUNTA('Sign-ups'!$A$2:$A$51)*COUNTA('Sign-ups'!$B$2:$B$51),INDEX('Sign-ups'!$B$2:$B$51,MOD(MOD((ROW()-2),MAX(1,COUNTA('Sign-ups'!$A$2:$A$51)))+INT((ROW()-2)/MAX(1,COUNTA('Sign-ups'!$A$2:$A$51))),MAX(1,COUNTA('Sign-ups'!$B$2:$B$51)))+1),"") -> Cody Reeves | D4: =IF(AND(B4<>"",C4<>"",B4<>C4),1,0) -> 1 | E4: =E3+D4 -> 3
A5: =(ROW()-2) -> 3 | B5: =IF((ROW()-2)<COUNTA('Sign-ups'!$A$2:$A$51)*COUNTA('Sign-ups'!$B$2:$B$51),INDEX('Sign-ups'!$A$2:$A$51,MOD((ROW()-2),MAX(1,COUNTA('Sign-ups'!$A$2:$A$51)))+1),"") -> Jess McCoy | C5: =IF((ROW()-2)<COUNTA('Sign-ups'!$A$2:$A$51)*COUNTA('Sign-ups'!$B$2:$B$51),INDEX('Sign-ups'!$B$2:$B$51,MOD(MOD((ROW()-2),MAX(1,COUNTA('Sign-ups'!$A$2:$A$51)))+INT((ROW()-2)/MAX(1,COUNTA('Sign-ups'!$A$2:$A$51))),MAX(1,COUNTA('Sign-ups'!$B$2:$B$51)))+1),"") -> Hank Daniels | D5: =IF(AND(B5<>"",C5<>"",B5<>C5),1,0) -> 1 | E5: =E4+D5 -> 4
A6: =(ROW()-2) -> 4 | B6: =IF((ROW()-2)<COUNTA('Sign-ups'!$A$2:$A$51)*COUNTA('Sign-ups'!$B$2:$B$51),INDEX('Sign-ups'!$A$2:$A$51,MOD((ROW()-2),MAX(1,COUNTA('Sign-ups'!$A$2:$A$51)))+1),"") -> Sam Tatum | C6: =IF((ROW()-2)<COUNTA('Sign-ups'!$A$2:$A$51)*COUNTA('Sign-ups'!$B$2:$B$51),INDEX('Sign-ups'!$B$2:$B$51,MOD(MOD((ROW()-2),MAX(1,COUNTA('Sign-ups'!$A$2:$A$51)))+INT((ROW()-2)/MAX(1,COUNTA('Sign-ups'!$A$2:$A$51))),MAX(1,COUNTA('Sign-ups'!$B$2:$B$51)))+1),"") -> Cole Briggs | D6: =IF(AND(B6<>"",C6<>"",B6<>C6),1,0) -> 1 | E6: =E5+D6 -> 5
A7: =(ROW()-2) -> 5 | B7: =IF((ROW()-2)<COUNTA('Sign-ups'!$A$2:$A$51)*COUNTA('Sign-ups'!$B$2:$B$51),INDEX('Sign-ups'!$A$2:$A$51,MOD((ROW()-2),MAX(1,COUNTA('Sign-ups'!$A$2:$A$51)))+1),"") -> Bo Whitaker | C7: =IF((ROW()-2)<COUNTA('Sign-ups'!$A$2:$A$51)*COUNTA('Sign-ups'!$B$2:$B$51),INDEX('Sign-ups'!$B$2:$B$51,MOD(MOD((ROW()-2),MAX(1,COUNTA('Sign-ups'!$A$2:$A$51)))+INT((ROW()-2)/MAX(1,COUNTA('Sign-ups'!$A$2:$A$51))),MAX(1,COUNTA('Sign-ups'!$B$2:$B$51)))+1),"") -> Tyler Branch | D7: =IF(AND(B7<>"",C7<>"",B7<>C7),1,0) -> 1 | E7: =E6+D7 -> 6
A8: =(ROW()-2) -> 6 | B8: =IF((ROW()-2)<COUNTA('Sign-ups'!$A$2:$A$51)*COUNTA('Sign-ups'!$B$2:$B$51),INDEX('Sign-ups'!$A$2:$A$51,MOD((ROW()-2),MAX(1,COUNTA('Sign-ups'!$A$2:$A$51)))+1),"") -> Cody Reeves | C8: =IF((ROW()-2)<COUNTA('Sign-ups'!$A$2:$A$51)*COUNTA('Sign-ups'!$B$2:$B$51),INDEX('Sign-ups'!$B$2:$B$51,MOD(MOD((ROW()-2),MAX(1,COUNTA('Sign-ups'!$A$2:$A$51)))+INT((ROW()-2)/MAX(1,COUNTA('Sign-ups'!$A$2:$A$51))),MAX(1,COUNTA('Sign-ups'!$B$2:$B$51)))+1),"") -> Luke Ramsey | D8: =IF(AND(B8<>"",C8<>"",B8<>C8),1,0) -> 1 | E8: =E7+D8 -> 7
A9: =(ROW()-2) -> 7 | B9: =IF((ROW()-2)<COUNTA('Sign-ups'!$A$2:$A$51)*COUNTA('Sign-ups'!$B$2:$B$51),INDEX('Sign-ups'!$A$2:$A$51,MOD((ROW()-2),MAX(1,COUNTA('Sign-ups'!$A$2:$A$51)))+1),"") -> Trevor James | C9: =IF((ROW()-2)<COUNTA('Sign-ups'!$A$2:$A$51)*COUNTA('Sign-ups'!$B$2:$B$51),INDEX('Sign-ups'!$B$2:$B$51,MOD(MOD((ROW()-2),MAX(1,COUNTA('Sign-ups'!$A$2:$A$51)))+INT((ROW()-2)/MAX(1,COUNTA('Sign-ups'!$A$2:$A$51))),MAX(1,COUNTA('Sign-ups'!$B$2:$B$51)))+1),"") -> Cody Reeves | D9: =IF(AND(B9<>"",C9<>"",B9<>C9),1,0) -> 1 | E9: =E8+D9 -> 8
A10: =(ROW()-2) -> 8 | B10: =IF((ROW()-2)<COUNTA('Sign-ups'!$A$2:$A$51)*COUNTA('Sign-ups'!$B$2:$B$51),INDEX('Sign-ups'!$A$2:$A$51,MOD((ROW()-2),MAX(1,COUNTA('Sign-ups'!$A$2:$A$51)))+1),"") -> Wyatt Holloway | C10: =IF((ROW()-2)<COUNTA('Sign-ups'!$A$2:$A$51)*COUNTA('Sign-ups'!$B$2:$B$51),INDEX('Sign-ups'!$B$2:$B$51,MOD(MOD((ROW()-2),MAX(1,COUNTA('Sign-ups'!$A$2:$A$51)))+INT((ROW()-2)/MAX(1,COUNTA('Sign-ups'!$A$2:$A$51))),MAX(1,COUNTA('Sign-ups'!$B$2:$B$51)))+1),"") -> Hank Daniels | D10: =IF(AND(B10<>"",C10<>"",B10<>C10),1,0) -> 1 | E10: =E9+D10 -> 9
A11: =(ROW()-2) -> 9 | B11: =IF((ROW()-2)<COUNTA('Sign-ups'!$A$2:$A$51)*COUNTA('Sign-ups'!$B$2:$B$51),INDEX('Sign-ups'!$A$2:$A$51,MOD((ROW()-2),MAX(1,COUNTA('Sign-ups'!$A$2:$A$51)))+1),"") -> Jess McCoy | C11: =IF((ROW()-2)<COUNTA('Sign-ups'!$A$2:$A$51)*COUNTA('Sign-ups'!$B$2:$B$51),INDEX('Sign-ups'!$B$2:$B$51,MOD(MOD((ROW()-2),MAX(1,COUNTA('Sign-ups'!$A$2:$A$51)))+INT((ROW()-2)/MAX(1,COUNTA('Sign-ups'!$A$2:$A$51))),MAX(1,COUNTA('Sign-ups'!$B$2:$B$51)))+1),"") -> Cole Briggs | D11: =IF(AND(B11<>"",C11<>"",B11<>C11),1,0) -> 1 | E11: =E10+D11 -> 10
A12: =(ROW()-2) -> 10 | B12: =IF((ROW()-2)<COUNTA('Sign-ups'!$A$2:$A$51)*COUNTA('Sign-ups'!$B$2:$B$51),INDEX('Sign-ups'!$A$2:$A$51,MOD((ROW()-2),MAX(1,COUNTA('Sign-ups'!$A$2:$A$51)))+1),"") -> Sam Tatum | C12: =IF((ROW()-2)<COUNTA('Sign-ups'!$A$2:$A$51)*COUNTA('Sign-ups'!$B$2:$B$51),INDEX('Sign-ups'!$B$2:$B$51,MOD(MOD((ROW()-2),MAX(1,COUNTA('Sign-ups'!$A$2:$A$51)))+INT((ROW()-2)/MAX(1,COUNTA('Sign-ups'!$A$2:$A$51))),MAX(1,COUNTA('Sign-ups'!$B$2:$B$51)))+1),"") -> Tyler Branch | D12: =IF(AND(B12<>"",C12<>"",B12<>C12),1,0) -> 1 | E12: =E11+D12 -> 11
A13: =(ROW()-2) -> 11 | B13: =IF((ROW()-2)<COUNTA('Sign-ups'!$A$2:$A$51)*COUNTA('Sign-ups'!$B$2:$B$51),INDEX('Sign-ups'!$A$2:$A$51,MOD((ROW()-2),MAX(1,COUNTA('Sign-ups'!$A$2:$A$51)))+1),"") -> Bo Whitaker | C13: =IF((ROW()-2)<COUNTA('Sign-ups'!$A$2:$A$51)*COUNTA('Sign-ups'!$B$2:$B$51),INDEX('Sign-ups'!$B$2:$B$51,MOD(MOD((ROW()-2),MAX(1,COUNTA('Sign-ups'!$A$2:$A$51)))+INT((ROW()-2)/MAX(1,COUNTA('Sign-ups'!$A$2:$A$51))),MAX(1,COUNTA('Sign-ups'!$B$2:$B$51)))+1),"") -> Luke Ramsey | D13: =IF(AND(B13<>"",C13<>"",B13<>C13),1,0) -> 1 | E13: =E12+D13 -> 12
A14: =(ROW()-2) -> 12 | B14: =IF((ROW()-2)<COUNTA('Sign-ups'!$A$2:$A$51)*COUNTA('Sign-ups'!$B$2:$B$51),INDEX('Sign-ups'!$A$2:$A$51,MOD((ROW()-2),MAX(1,COUNTA('Sign-ups'!$A$2:$A$51)))+1),"") -> Cody Reeves | C14: =IF((ROW()-2)<COUNTA('Sign-ups'!$A$2:$A$51)*COUNTA('Sign-ups'!$B$2:$B$51),INDEX('Sign-ups'!$B$2:$B$51,MOD(MOD((ROW()-2),MAX(1,COUNTA('Sign-ups'!$A$2:$A$51)))+INT((ROW()-2)/MAX(1,COUNTA('Sign-ups'!$A$2:$A$51))),MAX(1,COUNTA('Sign-ups'!$B$2:$B$51)))+1),"") -> Cody Reeves | D14: =IF(AND(B14<>"",C14<>"",B14<>C14),1,0) -> 0 | E14: =E13+D14 -> 12
... A2501: =(ROW()-2) -> 2499 | B2501: =IF((ROW()-2)<COUNTA('Sign-ups'!$A$2:$A$51)*COUNTA('Sign-ups'!$B$2:$B$51),INDEX('Sign-ups'!$A$2:$A$51,MOD((ROW()-2),MAX(1,COUNTA('Sign-ups'!$A$2:$A$51)))+1),"") | C2501: =IF((ROW()-2)<COUNTA('Sign-ups'!$A$2:$A$51)*COUNTA('Sign-ups'!$B$2:$B$51),INDEX('Sign-ups'!$B$2:$B$51,MOD(MOD((ROW()-2),MAX(1,COUNTA('Sign-ups'!$A$2:$A$51)))+INT((ROW()-2)/MAX(1,COUNTA('Sign-ups'!$A$2:$A$51))),MAX(1,COUNTA('Sign-ups'!$B$2:$B$51)))+1),"") | D2501: =IF(AND(B2501<>"",C2501<>"",B2501<>C2501),1,0) -> 0 | E2501: =E2500+D2501 -> 29
